Workbook

Sheet Proforma
A1: ='Room Types'!A1 -> Hotel xxxx
A2: For Discussion Purposes Only
A3: JPY
D5: Proforma | G5: =D5 -> Proforma | J5: =G5 -> Proforma | M5: =J5 -> Proforma | P5: =M5 -> Proforma | S5: (before c tax) | T5: =#REF! -> #REF!
D6: Year 1 | G6: Year 2 | J6: Year 3 | M6: Year 4 | P6: Year 5 | S6: Project Costs | T6: Cost | U6: per room
S8: Purchase Price (inc FF&E) | U8: =ROUND(T8/$P$11,-4) -> 0
B9: KPIs | F9: % Grth | I9: % Grth | L9: % Grth | O9: % Grth | S9: New Signage, etc. | U9: =ROUND(T9/$P$11,-4) -> 0
B10: No of Days | D10: =Rooms!S7 -> 365 | G10: =D10 -> 365 | J10: =G10 -> 365 | M10: =J10 -> 365 | P10: =M10 -> 365 | S10: OSE, etc | U10: =ROUND(T10/$P$11,-4) -> 0
B11: No of Rooms | D11: =Rooms!G8 -> 207 | G11: =D11 -> 207 | J11: =G11 -> 207 | M11: =J11 -> 207 | P11: =M11 -> 207 | S11: Re-Branding Cost | U11: =ROUND(T11/$P$11,-4) -> 0 | V11: 0 | W11: mos
B12: Available Room Nights | D12: =Rooms!S9 -> 75555 | G12: =G10*G11 -> 75555 | J12: =J10*J11 -> 75555 | M12: =M10*M11 -> 75555 | P12: =P10*P11 -> 75555 | S12: Working Capital | T12: =ROUND((($S$54+$S$82)/12)*V12,-6) -> 72000000 | U12: =ROUND(T12/$P$11,-4) -> 350000 | V12: 1 | W12: mos
B13: Occupied Room Nights | D13: =Rooms!S10 -> 65060.15 | G13: =G12*G14 -> 67326.8 | J13: =J12*J14 -> 69593.45 | M13: =M12*M14 -> 71104.55 | P13: =P12*P14 -> 72237.875 | S13: Operator's Tech Fee | U13: =ROUND(T13/$P$11,-4) -> 0
B14: Occupancy | D14: =D13/D12 -> 0.86109656 | F14: 0.03 | G14: =D14+F14 -> 0.89109656 | I14: 0.03 | J14: =G14+I14 -> 0.92109656 | L14: 0.02 | M14: =J14+L14 -> 0.94109656 | O14: 0.015 | P14: =M14+O14 -> 0.95609656 | S14: Total Cost | T14: =SUM(T8:T13) -> 72000000 | U14: =SUM(U8:U13) -> 350000
B15: ADR | D15: =Rooms!S12 -> 10000 | F15: 0.03 | G15: =D15*(1+F15) -> 10300 | I15: 0.03 | J15: =G15*(1+I15) -> 10609 | L15: 0.02 | M15: =J15*(1+L15) -> 10821.18 | O15: 0.02 | P15: =M15*(1+O15) -> 11037.604
B16: RevPar | D16: =D14*D15 -> 8610.9656 | G16: =G14*G15 -> 9178.2945 | J16: =J14*J15 -> 9771.9134 | M16: =M14*M15 -> 10183.775 | P16: =P14*P15 -> 10553.015
B17: No of Hotel Guests | D17: =Rooms!S14 -> 130120.3 | F17: =G17/D17-1 -> 0.034839298 | G17: =G18*G13 -> 134653.6 | I17: =J17/G17-1 -> 0.033666385 | J17: =J18*J13 -> 139186.9 | L17: =M17/J17-1 -> 0.02171325 | M17: =M18*M13 -> 142209.1 | O17: =P17/M17-1 -> 0.015938853 | P17: =P18*P13 -> 144475.75
B18: No of Guest / Occ Room | D18: =D17/D13 -> 2 | G18: =D18 -> 2 | J18: =G18 -> 2 | M18: =J18 -> 2 | P18: =M18 -> 2
B21: Personnel (FT) | D21: =Staffing!C51 -> 20 | G21: =Staffing!E51 -> 20 | J21: =Staffing!G51 -> 20 | M21: =Staffing!I51 -> 20 | P21: =Staffing!K51 -> 20
B22: Personnel (PT) | D22: =Staffing!C52 -> 28 | G22: =Staffing!E52 -> 28 | J22: =Staffing!G52 -> 28 | M22: =Staffing!I52 -> 28 | P22: =Staffing!K52 -> 28
B23: Total Personnel | D23: =SUM(D21:D22) -> 48 | G23: =G21+G22 -> 48 | J23: =J21+J22 -> 48 | M23: =M21+M22 -> 48 | P23: =P21+P22 -> 48
B24: Personnel Costs | D24: =Staffing!D21 -> 189631360 | E24: =D24/D30 -> 0.15297631 | G24: =Staffing!F21 -> 189631360 | H24: =G24/G30 -> 0.14553467 | J24: =Staffing!H21 -> 189631360 | K24: =J24/J30 -> 0.13858199 | M24: =Staffing!J21 -> 189631360 | N24: =M24/M30 -> 0.13418882 | P24: =Staffing!L21 -> 189631360 | Q24: =P24/P30 -> 0.13066072
B26: Revenues | E26: % Rev | F26: % Grth | H26: % Rev | I26: % Grth | K26: % Rev | L26: % Grth | N26: % Rev | O26: % Grth | Q26: % Rev
B27: Rooms | D27: =Rooms!G192 -> 6.506015e+08 | E27: =D27/D$30 -> 0.52484262 | G27: =G13*G15 -> 6.9346604e+08 | H27: =G27/G$30 -> 0.53220813 | J27: =J13*J15 -> 7.3831692e+08 | K27: =J27/J$30 -> 0.53955964 | M27: =M13*M15 -> 7.6943514e+08 | N27: =M27/M$30 -> 0.54447529 | P27: =P13*P15 -> 7.9733303e+08 | Q27: =P27/P$30 -> 0.5493823
B28: Restaurant | D28: =Restaurant!E175 -> 5.6936504e+08 | E28: =D28/D$30 -> 0.45930887 | F28: =F17 -> 0.034839298 | G28: =D28*(1+F28) -> 5.8920132e+08 | H28: =G28/G$30 -> 0.45218902 | I28: =I17 -> 0.033666385 | J28: =G28*(1+I28) -> 6.0903759e+08 | K28: =J28/J$30 -> 0.44508272 | L28: =L17 -> 0.02171325 | M28: =J28*(1+L28) -> 6.2226178e+08 | N28: =M28/M$30 -> 0.44033103 | O28: =O17 -> 0.015938853 | P28: =M28*(1+O28) -> 6.3217992e+08 | Q28: =P28/P$30 -> 0.43558769
B29: MOD | D29: =MOD!E102 -> 19646015 | E29: =D29/D$30 -> 0.015848512 | F29: =F17 -> 0.034839298 | G29: =D29*(1+F29) -> 20330468 | H29: =G29/G$30 -> 0.015602841 | I29: =I17 -> 0.033666385 | J29: =G29*(1+I29) -> 21014922 | K29: =J29/J$30 -> 0.015357638 | L29: =L17 -> 0.02171325 | M29: =J29*(1+L29) -> 21471224 | N29: =M29/M$30 -> 0.01519368 | O29: =O17 -> 0.015938853 | P29: =M29*(1+O29) -> 21813451 | Q29: =P29/P$30 -> 0.01503001
B30: Total | D30: =D27+D28+D29 -> 1.2396126e+09 | E30: =E27+E28+E29 -> 1 | G30: =G27+G28+G29 -> 1.3029978e+09 | H30: =H27+H28+H29 -> 1 | J30: =J27+J28+J29 -> 1.3683694e+09 | K30: =K27+K28+K29 -> 1 | M30: =M27+M28+M29 -> 1.4131681e+09 | N30: =N27+N28+N29 -> 1 | P30: =P27+P28+P29 -> 1.4513264e+09 | Q30: =Q27+Q28+Q29 -> 1
B32: COGS
B33: Rooms | D33: =Rooms!G193 -> 0 | E33: =IFERROR(D33/D27,0) -> 0 | G33: =D33 -> 0 | H33: =IFERROR(G33/G27,0) -> 0 | J33: =G33 -> 0 | K33: =IFERROR(J33/J27,0) -> 0 | M33: =J33 -> 0 | N33: =IFERROR(M33/M27,0) -> 0 | P33: =M33 -> 0 | Q33: =IFERROR(P33/P27,0) -> 0
B34: Restaurant | D34: =Restaurant!E177 -> 1.9927776e+08 | E34: =IFERROR(D34/D28,0) -> 0.35 | F34: =F22 -> 0 | G34: =G28*(E34+F34) -> 2.0622046e+08 | H34: =IFERROR(G34/G28,0) -> 0.35 | I34: =I22 -> 0 | J34: =J28*(H34+I34) -> 2.1316316e+08 | K34: =IFERROR(J34/J28,0) -> 0.35 | L34: =L22 -> 0 | M34: =M28*(K34+L34) -> 2.1779162e+08 | N34: =IFERROR(M34/M28,0) -> 0.35 | O34: =O22 -> 0 | P34: =P28*(N34+O34) -> 2.2126297e+08 | Q34: =IFERROR(P34/P28,0) -> 0.35
B35: MOD | D35: =MOD!E104 -> 9823007.5 | E35: =IFERROR(D35/D29,0) -> 0.5 | F35: =F23 -> 0 | G35: =G29*(E35+F35) -> 10165234 | H35: =IFERROR(G35/G29,0) -> 0.5 | I35: =I23 -> 0 | J35: =J29*(H35+I35) -> 10507461 | K35: =IFERROR(J35/J29,0) -> 0.5 | L35: =L23 -> 0 | M35: =M29*(K35+L35) -> 10735612 | N35: =IFERROR(M35/M29,0) -> 0.5 | O35: =O23 -> 0 | P35: =P29*(N35+O35) -> 10906725 | Q35: =IFERROR(P35/P29,0) -> 0.5
B36: Total | D36: =D33+D34+D35 -> 2.0910077e+08 | E36: =D36/D$30 -> 0.16868236 | G36: =G33+G34+G35 -> 2.1638569e+08 | H36: =G36/G$30 -> 0.16606758 | J36: =J33+J34+J35 -> 2.2367062e+08 | K36: =J36/J$30 -> 0.16345777 | M36: =M33+M34+M35 -> 2.2852724e+08 | N36: =M36/M$30 -> 0.1617127 | P36: =P33+P34+P35 -> 2.321697e+08 | Q36: =P36/P$30 -> 0.1599707
B38: Personnel Expense
B39: Rooms | D39: =Rooms!G169 -> 55306560 | E39: =IFERROR(D39/D27,0) -> 0.085008349 | F39: Dept | G39: =Rooms!H169 -> 55306560 | H39: =IFERROR(G39/G27,0) -> 0.079753811 | I39: Dept | J39: =Rooms!I169 -> 55306560 | K39: =IFERROR(J39/J27,0) -> 0.07490897 | L39: Dept | M39: =Rooms!J169 -> 55306560 | N39: =IFERROR(M39/M27,0) -> 0.071879431 | O39: Dept | P39: =Rooms!K169 -> 55306560 | Q39: =IFERROR(P39/P27,0) -> 0.069364441
B40: Restaurant | D40: =Restaurant!E164 -> 124460800 | E40: =IFERROR(D40/D28,0) -> 0.21859579 | F40: Dept | G40: =Restaurant!F164 -> 124460800 | H40: =IFERROR(G40/G28,0) -> 0.21123646 | I40: Dept | J40: =Restaurant!G164 -> 124460800 | K40: =IFERROR(J40/J28,0) -> 0.20435651 | L40: Dept | M40: =Restaurant!H164 -> 124460800 | N40: =IFERROR(M40/M28,0) -> 0.20001357 | O40: Dept | P40: =Restaurant!I164 -> 124460800 | Q40: =IFERROR(P40/P28,0) -> 0.1968756
B41: MOD | D41: =MOD!E91 -> 0 | E41: =IFERROR(D41/D29,0) -> 0 | F41: Dept | G41: =MOD!F81 -> 0 | H41: =IFERROR(G41/G29,0) -> 0 | I41: Dept | J41: =MOD!G91 -> 0 | K41: =IFERROR(J41/J29,0) -> 0 | L41: Dept | M41: =MOD!H91 -> 0 | N41: =IFERROR(M41/M29,0) -> 0 | O41: Dept | P41: =MOD!I91 -> 0 | Q41: =IFERROR(P41/P29,0) -> 0
B42: Total | D42: =D39+D40+D41 -> 179767360 | E42: =D42/D$30 -> 0.14501899 | G42: =G39+G40+G41 -> 179767360 | H42: =G42/G$30 -> 0.13796444 | J42: =J39+J40+J41 -> 179767360 | K42: =J42/J$30 -> 0.13137341 | M42: =M39+M40+M41 -> 179767360 | N42: =M42/M$30 -> 0.12720875 | P42: =P39+P40+P41 -> 179767360 | Q42: =P42/P$30 -> 0.12386418
B44: Other Expense
B45: Rooms | D45: =Rooms!G195 -> 2.3746955e+08 | E45: =IFERROR(D45/D27,0) -> 0.365 | F45: =F33 -> 0 | G45: =G27*(E45+F45) -> 2.5311511e+08 | H45: =IFERROR(G45/G27,0) -> 0.365 | I45: =I33 -> 0 | J45: =J27*(H45+I45) -> 2.6948567e+08 | K45: =IFERROR(J45/J27,0) -> 0.365 | L45: =L33 -> 0 | M45: =M27*(K45+L45) -> 2.8084382e+08 | N45: =IFERROR(M45/M27,0) -> 0.365 | O45: =O33 -> 0 | P45: =P27*(N45+O45) -> 2.9102656e+08 | Q45: =IFERROR(P45/P27,0) -> 0.365
B46: Restaurant | D46: =Restaurant!E178 -> 28468252 | E46: =IFERROR(D46/D28,0) -> 0.05 | F46: =F34 -> 0 | G46: =G28*(E46+F46) -> 29460066 | H46: =IFERROR(G46/G28,0) -> 0.05 | I46: =I34 -> 0 | J46: =J28*(H46+I46) -> 30451880 | K46: =IFERROR(J46/J28,0) -> 0.05 | L46: =L34 -> 0 | M46: =M28*(K46+L46) -> 31113089 | N46: =IFERROR(M46/M28,0) -> 0.05 | O46: =O34 -> 0 | P46: =P28*(N46+O46) -> 31608996 | Q46: =IFERROR(P46/P28,0) -> 0.05
B47: MOD | D47: =MOD!E105 -> 0 | E47: =IFERROR(D47/D29,0) -> 0 | F47: =F35 -> 0 | G47: =G29*(E47+F47) -> 0 | H47: =IFERROR(G47/G29,0) -> 0 | I47: =I35 -> 0 | J47: =J29*(H47+I47) -> 0 | K47: =IFERROR(J47/J29,0) -> 0 | L47: =L35 -> 0 | M47: =M29*(K47+L47) -> 0 | N47: =IFERROR(M47/M29,0) -> 0 | O47: =O35 -> 0 | P47: =P29*(N47+O47) -> 0 | Q47: =IFERROR(P47/P29,0) -> 0
B48: Total | D48: =D45+D46+D47 -> 2.659378e+08 | E48: =D48/D$30 -> 0.214533 | G48: =G45+G46+G47 -> 2.8257517e+08 | H48: =G48/G$30 -> 0.21686542 | J48: =J45+J46+J47 -> 2.9993755e+08 | K48: =J48/J$30 -> 0.2191934 | M48: =M45+M46+M47 -> 3.1195691e+08 | N48: =M48/M$30 -> 0.22075003 | P48: =P45+P46+P47 -> 3.2263555e+08 | Q48: =P48/P$30 -> 0.22230392
...

Sheet Rooms
A1: ='Room Types'!$A$1 -> Hotel xxxx | G1: Year 1
A2: Room Revenues | D2: No of Rooms | E2: =E30 -> 207
A3: JPY
G5: Month
C6: Year 1 | G6: 1 | H6: =G6+1 -> 2 | I6: =H6+1 -> 3 | J6: =I6+1 -> 4 | K6: =J6+1 -> 5 | L6: =K6+1 -> 6 | M6: =L6+1 -> 7 | N6: =M6+1 -> 8 | O6: =N6+1 -> 9 | ... R6: =Q6+1 -> 12 | S6: Total
C7: No of Days (all) | G7: 31 | H7: 28 | I7: 31 | J7: 30 | K7: 31 | L7: 30 | M7: 31 | N7: 31 | O7: 30 | P7: 31 | Q7: 30 | R7: 31 | S7: =SUM(G7:R7) -> 365
C8: Number of Rooms | G8: =E30 -> 207 | H8: =G8 -> 207 | I8: =H8 -> 207 | J8: =I8 -> 207 | K8: =J8 -> 207 | L8: =K8 -> 207 | M8: =L8 -> 207 | N8: =M8 -> 207 | O8: =N8 -> 207 | ... R8: =Q8 -> 207 | S8: =SUM(G8:R8) -> 2484
C9: Available Room Nights | G9: =G7*G8 -> 6417 | H9: =H7*H8 -> 5796 | I9: =I7*I8 -> 6417 | J9: =J7*J8 -> 6210 | K9: =K7*K8 -> 6417 | L9: =L7*L8 -> 6210 | M9: =M7*M8 -> 6417 | N9: =N7*N8 -> 6417 | ... R9: =R7*R8 -> 6417 | S9: =SUM(G9:R9) -> 75555
C10: Occupied Room Nights | G10: =G30 -> 5133.6 | H10: =H30 -> 4876.5554 | I10: =I30 -> 5199.7493 | J10: =J30 -> 4419.7608 | K10: =K30 -> 5652.8978 | L10: =L30 -> 5785.9776 | M10: =M30 -> 5873.7426 | N10: =N30 -> 5879.9929 | ... R10: =R30 -> 5475.024 | S10: =SUM(G10:R10) -> 65060.15
C11: Occupancy | G11: =G10/G9 -> 0.8 | H11: =H10/H9 -> 0.84136567 | I11: =I10/I9 -> 0.81030844 | J11: =J10/J9 -> 0.71171672 | K11: =K10/K9 -> 0.88092532 | L11: =L10/L9 -> 0.93171943 | M11: =M10/M9 -> 0.91534091 | N11: =N10/N9 -> 0.91631494 | ... S11: =S10/S9 -> 0.86109656
C12: ADR | G12: =G63 -> 10000 | H12: =H63 -> 10000 | I12: =I63 -> 10000 | J12: =J63 -> 10000 | K12: =K63 -> 10000 | L12: =L63 -> 10000 | M12: =M63 -> 10000 | N12: =N63 -> 10000 | ... S12: =S63 -> 10000
C13: RevPar | G13: =G11*G12 -> 8000 | H13: =H11*H12 -> 8413.6567 | I13: =I11*I12 -> 8103.0844 | J13: =J11*J12 -> 7117.1672 | K13: =K11*K12 -> 8809.2532 | L13: =L11*L12 -> 9317.1943 | M13: =M11*M12 -> 9153.4091 | N13: =N11*N12 -> 9163.1494 | ... S13: =S11*S12 -> 8610.9656
C14: Total Guest Count | E14: 2 | G14: =$E$14*G10 -> 10267.2 | H14: =$E$14*H10 -> 9753.1108 | I14: =$E$14*I10 -> 10399.499 | J14: =$E$14*J10 -> 8839.5217 | K14: =$E$14*K10 -> 11305.796 | L14: =$E$14*L10 -> 11571.955 | M14: =$E$14*M10 -> 11747.485 | N14: =$E$14*N10 -> 11759.986 | ... R14: =$E$14*R10 -> 10950.048 | S14: =SUM(G14:R14) -> 130120.3
C15: No of Guests per Day | G15: =G14/G7 -> 331.2 | H15: =H14/H7 -> 348.32539 | I15: =I14/I7 -> 335.46769 | J15: =J14/J7 -> 294.65072 | K15: =K14/K7 -> 364.70308 | L15: =L14/L7 -> 385.73184 | M15: =M14/M7 -> 378.95114 | N15: =N14/N7 -> 379.35438 | ... S15: =S14/S7 -> 356.49397
C18: Room Nights
C19: Type | D19: Size (sqm) | E19: Rooms
B20: 1 | C20: ='Room Types'!C7 -> King | D20: ='Room Types'!H7 -> 27 | E20: ='Room Types'!D7 -> 100 | G20: =G$7*G35*$E20 -> 2480 | H20: =H$7*H35*$E20 -> 2355.8239 | I20: =I$7*I35*$E20 -> 2511.9562 | J20: =J$7*J35*$E20 -> 2135.1502 | K20: =K$7*K35*$E20 -> 2730.8685 | L20: =L$7*L35*$E20 -> 2795.1583 | M20: =M$7*M35*$E20 -> 2837.5568 | N20: =N$7*N35*$E20 -> 2840.5763 | ... R20: =R$7*R35*$E20 -> 2644.9391 | S20: =SUM(G20:R20) -> 31430.024 | T20: =S20/($S$7*E20) -> 0.86109656
B21: =B20+1 -> 2 | C21: ='Room Types'!C8 -> 0 | D21: ='Room Types'!H8 -> 0 | E21: ='Room Types'!D8 -> 0 | G21: =G$7*G36*$E21 -> 0 | H21: =H$7*H36*$E21 -> 0 | I21: =I$7*I36*$E21 -> 0 | J21: =J$7*J36*$E21 -> 0 | K21: =K$7*K36*$E21 -> 0 | L21: =L$7*L36*$E21 -> 0 | M21: =M$7*M36*$E21 -> 0 | N21: =N$7*N36*$E21 -> 0 | ... R21: =R$7*R36*$E21 -> 0 | S21: =SUM(G21:R21) -> 0 | T21: =S21/($S$7*E21) -> #DIV/0!
B22: =B21+1 -> 3 | C22: ='Room Types'!C9 -> Double Double | D22: ='Room Types'!H9 -> 28.3 | E22: ='Room Types'!D9 -> 100 | G22: =G$7*G37*$E22 -> 2480 | H22: =H$7*H37*$E22 -> 2355.8239 | I22: =I$7*I37*$E22 -> 2511.9562 | J22: =J$7*J37*$E22 -> 2135.1502 | K22: =K$7*K37*$E22 -> 2730.8685 | L22: =L$7*L37*$E22 -> 2795.1583 | M22: =M$7*M37*$E22 -> 2837.5568 | N22: =N$7*N37*$E22 -> 2840.5763 | ... R22: =R$7*R37*$E22 -> 2644.9391 | S22: =SUM(G22:R22) -> 31430.024 | T22: =S22/($S$7*E22) -> 0.86109656
B23: =B22+1 -> 4 | C23: ='Room Types'!C10 -> 0 | D23: ='Room Types'!H10 -> 0 | E23: ='Room Types'!D10 -> 0 | G23: =G$7*G38*$E23 -> 0 | H23: =H$7*H38*$E23 -> 0 | I23: =I$7*I38*$E23 -> 0 | J23: =J$7*J38*$E23 -> 0 | K23: =K$7*K38*$E23 -> 0 | L23: =L$7*L38*$E23 -> 0 | M23: =M$7*M38*$E23 -> 0 | N23: =N$7*N38*$E23 -> 0 | ... R23: =R$7*R38*$E23 -> 0 | S23: =SUM(G23:R23) -> 0 | T23: =S23/($S$7*E23) -> #DIV/0!
B24: =B23+1 -> 5 | C24: ='Room Types'!C11 -> 0 | D24: ='Room Types'!H11 -> 0 | E24: ='Room Types'!D11 -> 0 | G24: =G$7*G39*$E24 -> 0 | H24: =H$7*H39*$E24 -> 0 | I24: =I$7*I39*$E24 -> 0 | J24: =J$7*J39*$E24 -> 0 | K24: =K$7*K39*$E24 -> 0 | L24: =L$7*L39*$E24 -> 0 | M24: =M$7*M39*$E24 -> 0 | N24: =N$7*N39*$E24 -> 0 | ... R24: =R$7*R39*$E24 -> 0 | S24: =SUM(G24:R24) -> 0 | T24: =S24/($S$7*E24) -> #DIV/0!
B25: =B24+1 -> 6 | C25: ='Room Types'!C12 -> 0 | D25: ='Room Types'!H12 -> 0 | E25: ='Room Types'!D12 -> 0 | G25: =G$7*G40*$E25 -> 0 | H25: =H$7*H40*$E25 -> 0 | I25: =I$7*I40*$E25 -> 0 | J25: =J$7*J40*$E25 -> 0 | K25: =K$7*K40*$E25 -> 0 | L25: =L$7*L40*$E25 -> 0 | M25: =M$7*M40*$E25 -> 0 | N25: =N$7*N40*$E25 -> 0 | ... R25: =R$7*R40*$E25 -> 0 | S25: =SUM(G25:R25) -> 0 | T25: =S25/($S$7*E25) -> #DIV/0!
B26: =B25+1 -> 7 | C26: ='Room Types'!C13 -> Junior Suite | D26: ='Room Types'!H13 -> 54 | E26: ='Room Types'!D13 -> 5 | G26: =G$7*G41*$E26 -> 124 | H26: =H$7*H41*$E26 -> 117.79119 | I26: =I$7*I41*$E26 -> 125.59781 | J26: =J$7*J41*$E26 -> 106.75751 | K26: =K$7*K41*$E26 -> 136.54343 | L26: =L$7*L41*$E26 -> 139.75791 | M26: =M$7*M41*$E26 -> 141.87784 | N26: =N$7*N41*$E26 -> 142.02881 | ... R26: =R$7*R41*$E26 -> 132.24696 | S26: =SUM(G26:R26) -> 1571.5012 | T26: =S26/($S$7*E26) -> 0.86109656
B27: =B26+1 -> 8 | C27: ='Room Types'!C14 -> Family Suite | D27: ='Room Types'!H14 -> 56.6 | E27: ='Room Types'!D14 -> 1 | G27: =G$7*G42*$E27 -> 24.8 | H27: =H$7*H42*$E27 -> 23.558239 | I27: =I$7*I42*$E27 -> 25.119562 | J27: =J$7*J42*$E27 -> 21.351502 | K27: =K$7*K42*$E27 -> 27.308685 | L27: =L$7*L42*$E27 -> 27.951583 | M27: =M$7*M42*$E27 -> 28.375568 | N27: =N$7*N42*$E27 -> 28.405763 | ... R27: =R$7*R42*$E27 -> 26.449391 | S27: =SUM(G27:R27) -> 314.30024 | T27: =S27/($S$7*E27) -> 0.86109656
B28: =B27+1 -> 9 | C28: ='Room Types'!C15 -> Exec. Suite | D28: ='Room Types'!H15 -> 81 | E28: ='Room Types'!D15 -> 1 | G28: =G$7*G43*$E28 -> 24.8 | H28: =H$7*H43*$E28 -> 23.558239 | I28: =I$7*I43*$E28 -> 25.119562 | J28: =J$7*J43*$E28 -> 21.351502 | K28: =K$7*K43*$E28 -> 27.308685 | L28: =L$7*L43*$E28 -> 27.951583 | M28: =M$7*M43*$E28 -> 28.375568 | N28: =N$7*N43*$E28 -> 28.405763 | ... R28: =R$7*R43*$E28 -> 26.449391 | S28: =SUM(G28:R28) -> 314.30024 | T28: =S28/($S$7*E28) -> 0.86109656
B29: =B28+1 -> 10 | C29: ='Room Types'!C16 -> 0 | D29: ='Room Types'!H16 -> 0 | E29: ='Room Types'!D16 -> 0 | G29: =G$7*G44*$E29 -> 0 | H29: =H$7*H44*$E29 -> 0 | I29: =I$7*I44*$E29 -> 0 | J29: =J$7*J44*$E29 -> 0 | K29: =K$7*K44*$E29 -> 0 | L29: =L$7*L44*$E29 -> 0 | M29: =M$7*M44*$E29 -> 0 | N29: =N$7*N44*$E29 -> 0 | ... R29: =R$7*R44*$E29 -> 0 | S29: =SUM(G29:R29) -> 0 | T29: =S29/($S$7*E29) -> #DIV/0!
C30: Total | D30: =SUMPRODUCT(D20:D29,E20:E29)/E30 -> 28.684058 | E30: =SUM(E20:E29) -> 207 | G30: =SUM(G20:G29) -> 5133.6 | H30: =SUM(H20:H29) -> 4876.5554 | I30: =SUM(I20:I29) -> 5199.7493 | J30: =SUM(J20:J29) -> 4419.7608 | K30: =SUM(K20:K29) -> 5652.8978 | L30: =SUM(L20:L29) -> 5785.9776 | M30: =SUM(M20:M29) -> 5873.7426 | N30: =SUM(N20:N29) -> 5879.9929 | ... R30: =SUM(R20:R29) -> 5475.024 | S30: =SUM(G30:R30) -> 65060.15 | T30: =S30/S9 -> 0.86109656
C33: Occupancy
C34: Type | D34: Size (sqm) | E34: Rooms
B35: 1 | C35: =C20 -> King | D35: =D20 -> 27 | E35: =E20 -> 100 | G35: 0.8 | H35: =$G35*H$46 -> 0.84136567 | I35: =$G35*I$46 -> 0.81030844 | J35: =$G35*J$46 -> 0.71171672 | K35: =$G35*K$46 -> 0.88092532 | L35: =$G35*L$46 -> 0.93171943 | M35: =$G35*M$46 -> 0.91534091 | N35: =$G35*N$46 -> 0.91631494 | O35: =$G35*O$46 -> 0.93150974 | ... R35: =$G35*R$46 -> 0.85320617 | S35: =S20/(E20*$S$7) -> 0.86109656
B36: =B35+1 -> 2 | C36: =C21 -> 0 | D36: =D21 -> 0 | E36: =E21 -> 0 | H36: =$G36*H$46 -> 0 | I36: =$G36*I$46 -> 0 | J36: =$G36*J$46 -> 0 | K36: =$G36*K$46 -> 0 | L36: =$G36*L$46 -> 0 | M36: =$G36*M$46 -> 0 | N36: =$G36*N$46 -> 0 | O36: =$G36*O$46 -> 0 | ... R36: =$G36*R$46 -> 0 | S36: =S21/(E21*$S$7) -> #DIV/0!
B37: =B36+1 -> 3 | C37: =C22 -> Double Double | D37: =D22 -> 28.3 | E37: =E22 -> 100 | G37: 0.8 | H37: =$G37*H$46 -> 0.84136567 | I37: =$G37*I$46 -> 0.81030844 | J37: =$G37*J$46 -> 0.71171672 | K37: =$G37*K$46 -> 0.88092532 | L37: =$G37*L$46 -> 0.93171943 | M37: =$G37*M$46 -> 0.91534091 | N37: =$G37*N$46 -> 0.91631494 | O37: =$G37*O$46 -> 0.93150974 | ... R37: =$G37*R$46 -> 0.85320617 | S37: =S22/(E22*$S$7) -> 0.86109656
B38: =B37+1 -> 4 | C38: =C23 -> 0 | D38: =D23 -> 0 | E38: =E23 -> 0 | H38: =$G38*H$46 -> 0 | I38: =$G38*I$46 -> 0 | J38: =$G38*J$46 -> 0 | K38: =$G38*K$46 -> 0 | L38: =$G38*L$46 -> 0 | M38: =$G38*M$46 -> 0 | N38: =$G38*N$46 -> 0 | O38: =$G38*O$46 -> 0 | ... R38: =$G38*R$46 -> 0 | S38: =S23/(E23*$S$7) -> #DIV/0!
B39: =B38+1 -> 5 | C39: =C24 -> 0 | D39: =D24 -> 0 | E39: =E24 -> 0 | H39: =$G39*H$46 -> 0 | I39: =$G39*I$46 -> 0 | J39: =$G39*J$46 -> 0 | K39: =$G39*K$46 -> 0 | L39: =$G39*L$46 -> 0 | M39: =$G39*M$46 -> 0 | N39: =$G39*N$46 -> 0 | O39: =$G39*O$46 -> 0 | ... R39: =$G39*R$46 -> 0 | S39: =S24/(E24*$S$7) -> #DIV/0!
B40: =B39+1 -> 6 | C40: =C25 -> 0 | D40: =D25 -> 0 | E40: =E25 -> 0 | H40: =$G40*H$46 -> 0 | I40: =$G40*I$46 -> 0 | J40: =$G40*J$46 -> 0 | K40: =$G40*K$46 -> 0 | L40: =$G40*L$46 -> 0 | M40: =$G40*M$46 -> 0 | N40: =$G40*N$46 -> 0 | O40: =$G40*O$46 -> 0 | ... R40: =$G40*R$46 -> 0 | S40: =S25/(E25*$S$7) -> #DIV/0!
B41: =B40+1 -> 7 | C41: =C26 -> Junior Suite | D41: =D26 -> 54 | E41: =E26 -> 5 | G41: 0.8 | H41: =$G41*H$46 -> 0.84136567 | I41: =$G41*I$46 -> 0.81030844 | J41: =$G41*J$46 -> 0.71171672 | K41: =$G41*K$46 -> 0.88092532 | L41: =$G41*L$46 -> 0.93171943 | M41: =$G41*M$46 -> 0.91534091 | N41: =$G41*N$46 -> 0.91631494 | O41: =$G41*O$46 -> 0.93150974 | ... R41: =$G41*R$46 -> 0.85320617 | S41: =S26/(E26*$S$7) -> 0.86109656
B42: =B41+1 -> 8 | C42: =C27 -> Family Suite | D42: =D27 -> 56.6 | E42: =E27 -> 1 | G42: 0.8 | H42: =$G42*H$46 -> 0.84136567 | I42: =$G42*I$46 -> 0.81030844 | J42: =$G42*J$46 -> 0.71171672 | K42: =$G42*K$46 -> 0.88092532 | L42: =$G42*L$46 -> 0.93171943 | M42: =$G42*M$46 -> 0.91534091 | N42: =$G42*N$46 -> 0.91631494 | O42: =$G42*O$46 -> 0.93150974 | ... R42: =$G42*R$46 -> 0.85320617 | S42: =S27/(E27*$S$7) -> 0.86109656
B43: =B42+1 -> 9 | C43: =C28 -> Exec. Suite | D43: =D28 -> 81 | E43: =E28 -> 1 | G43: 0.8 | H43: =$G43*H$46 -> 0.84136567 | I43: =$G43*I$46 -> 0.81030844 | J43: =$G43*J$46 -> 0.71171672 | K43: =$G43*K$46 -> 0.88092532 | L43: =$G43*L$46 -> 0.93171943 | M43: =$G43*M$46 -> 0.91534091 | N43: =$G43*N$46 -> 0.91631494 | O43: =$G43*O$46 -> 0.93150974 | ... R43: =$G43*R$46 -> 0.85320617 | S43: =S28/(E28*$S$7) -> 0.86109656
B44: =B43+1 -> 10 | C44: =C29 -> 0 | D44: =D29 -> 0 | E44: =E29 -> 0 | H44: =$G44*H$46 -> 0 | I44: =$G44*I$46 -> 0 | J44: =$G44*J$46 -> 0 | K44: =$G44*K$46 -> 0 | L44: =$G44*L$46 -> 0 | M44: =$G44*M$46 -> 0 | N44: =$G44*N$46 -> 0 | O44: =$G44*O$46 -> 0 | ... R44: =$G44*R$46 -> 0 | S44: =S29/(E29*$S$7) -> #DIV/0!
C45: Total | D45: =SUMPRODUCT(D35:D44,E35:E44)/E45 -> 28.684058 | E45: =SUM(E35:E44) -> 207 | G45: =G30/G9 -> 0.8 | H45: =H30/H9 -> 0.84136567 | I45: =I30/I9 -> 0.81030844 | J45: =J30/J9 -> 0.71171672 | K45: =K30/K9 -> 0.88092532 | L45: =L30/L9 -> 0.93171943 | M45: =M30/M9 -> 0.91534091 | N45: =N30/N9 -> 0.91631494 | ... S45: =S30/S9 -> 0.86109656 | T45: =S11 -> 0.86109656
...

Sheet Room Types
A1: Hotel xxxx
A2: Room Sizes
C6: Type | D6: No of Rooms | E6: Bed Size (cm) | F6: Room Size (sqm) Range | H6: Avg Room Size (sqm)
B7: 1 | C7: King | D7: 100 | F7: 27 | G7: 27 | H7: =AVERAGE(F7:G7) -> 27 | I7: =D7/$D$17 -> 0.48309179
B8: =B7+1 -> 2
B9: =B8+1 -> 3 | C9: Double Double | D9: 100 | F9: 28.3 | G9: 28.3 | H9: =AVERAGE(F9:G9) -> 28.3 | I9: =D9/$D$17 -> 0.48309179
B10: =B9+1 -> 4
B11: =B10+1 -> 5
B12: =B11+1 -> 6
B13: =B12+1 -> 7 | C13: Junior Suite | D13: 5 | F13: 54 | G13: 54 | H13: =AVERAGE(F13:G13) -> 54 | I13: =D13/$D$17 -> 0.024154589
B14: =B13+1 -> 8 | C14: Family Suite | D14: 1 | F14: 56.6 | G14: 56.6 | H14: =AVERAGE(F14:G14) -> 56.6 | I14: =D14/$D$17 -> 0.0048309179
B15: =B14+1 -> 9 | C15: Exec. Suite | D15: 1 | F15: 81 | G15: 81 | H15: =AVERAGE(F15:G15) -> 81 | I15: =D15/$D$17 -> 0.0048309179
B16: =B15+1 -> 10
C17: Total | D17: =SUM(D7:D16) -> 207 | H17: =SUMPRODUCT(D7:D16,H7:H16)/D17 -> 28.684058 | I17: =SUM(I7:I16) -> 1
G19: Total Room Area | H19: =SUMPRODUCT(H7:H16,D7:D16) -> 5937.6

Sheet Restaurant
A1: ='Room Types'!$A$1 -> Hotel xxxx
A2: ADD
A3: JPY
E6: Month
B7: Year 1 Total | E7: =Rooms!G6 -> 1 | F7: =Rooms!H6 -> 2 | G7: =Rooms!I6 -> 3 | H7: =Rooms!J6 -> 4 | I7: =Rooms!K6 -> 5 | J7: =Rooms!L6 -> 6 | K7: =Rooms!M6 -> 7 | L7: =Rooms!N6 -> 8 | ... P7: =Rooms!R6 -> 12 | Q7: Total
B8: No of Days | E8: =Rooms!G7 -> 31 | F8: =Rooms!H7 -> 28 | G8: =Rooms!I7 -> 31 | H8: =Rooms!J7 -> 30 | I8: =Rooms!K7 -> 31 | J8: =Rooms!L7 -> 30 | K8: =Rooms!M7 -> 31 | L8: =Rooms!N7 -> 31 | ... P8: =Rooms!R7 -> 31 | Q8: =SUM(E8:P8) -> 365
B9: Available Room Nights | E9: =Rooms!G9 -> 6417 | F9: =Rooms!H9 -> 5796 | G9: =Rooms!I9 -> 6417 | H9: =Rooms!J9 -> 6210 | I9: =Rooms!K9 -> 6417 | J9: =Rooms!L9 -> 6210 | K9: =Rooms!M9 -> 6417 | L9: =Rooms!N9 -> 6417 | ... P9: =Rooms!R9 -> 6417 | Q9: =SUM(E9:P9) -> 75555
B10: Occupied Room Nights | E10: =Rooms!G10 -> 5133.6 | F10: =Rooms!H10 -> 4876.5554 | G10: =Rooms!I10 -> 5199.7493 | H10: =Rooms!J10 -> 4419.7608 | I10: =Rooms!K10 -> 5652.8978 | J10: =Rooms!L10 -> 5785.9776 | K10: =Rooms!M10 -> 5873.7426 | L10: =Rooms!N10 -> 5879.9929 | ... P10: =Rooms!R10 -> 5475.024 | Q10: =SUM(E10:P10) -> 65060.15
B11: Occupancy | E11: =Rooms!G11 -> 0.8 | F11: =Rooms!H11 -> 0.84136567 | G11: =Rooms!I11 -> 0.81030844 | H11: =Rooms!J11 -> 0.71171672 | I11: =Rooms!K11 -> 0.88092532 | J11: =Rooms!L11 -> 0.93171943 | K11: =Rooms!M11 -> 0.91534091 | L11: =Rooms!N11 -> 0.91631494 | ... Q11: =Rooms!S11 -> 0.86109656
B12: ADR | E12: =Rooms!G12 -> 10000 | F12: =Rooms!H12 -> 10000 | G12: =Rooms!I12 -> 10000 | H12: =Rooms!J12 -> 10000 | I12: =Rooms!K12 -> 10000 | J12: =Rooms!L12 -> 10000 | K12: =Rooms!M12 -> 10000 | L12: =Rooms!N12 -> 10000 | ... Q12: =Rooms!S12 -> 10000
B13: RevPar | E13: =Rooms!G13 -> 8000 | F13: =Rooms!H13 -> 8413.6567 | G13: =Rooms!I13 -> 8103.0844 | H13: =Rooms!J13 -> 7117.1672 | I13: =Rooms!K13 -> 8809.2532 | J13: =Rooms!L13 -> 9317.1943 | K13: =Rooms!M13 -> 9153.4091 | L13: =Rooms!N13 -> 9163.1494 | ... Q13: =Rooms!S13 -> 8610.9656
B14: Total Guest Count | D14: =Q14/Q10 -> 2 | E14: =Rooms!G14 -> 10267.2 | F14: =Rooms!H14 -> 9753.1108 | G14: =Rooms!I14 -> 10399.499 | H14: =Rooms!J14 -> 8839.5217 | I14: =Rooms!K14 -> 11305.796 | J14: =Rooms!L14 -> 11571.955 | K14: =Rooms!M14 -> 11747.485 | L14: =Rooms!N14 -> 11759.986 | ... P14: =Rooms!R14 -> 10950.048 | Q14: =SUM(E14:P14) -> 130120.3
B15: No of Guests per Day | E15: =E14/E8 -> 331.2 | F15: =F14/F8 -> 348.32539 | G15: =G14/G8 -> 335.46769 | H15: =H14/H8 -> 294.65072 | I15: =I14/I8 -> 364.70308 | J15: =J14/J8 -> 385.73184 | K15: =K14/K8 -> 378.95114 | L15: =L14/L8 -> 379.35438 | ... Q15: =Q14/Q8 -> 356.49397
S16: Year 1
B17: Total Guest Count | D17: =D14 -> 2 | E17: =E14 -> 10267.2 | F17: =F14 -> 9753.1108 | G17: =G14 -> 10399.499 | H17: =H14 -> 8839.5217 | I17: =I14 -> 11305.796 | J17: =J14 -> 11571.955 | K17: =K14 -> 11747.485 | ... P17: =P14 -> 10950.048 | Q17: =SUM(E17:P17) -> 130120.3 | S17: =Rooms!S14 -> 130120.3
B18: per Day | E18: =E17/E8 -> 331.2 | F18: =F17/F8 -> 348.32539 | G18: =G17/G8 -> 335.46769 | H18: =H17/H8 -> 294.65072 | I18: =I17/I8 -> 364.70308 | J18: =J17/J8 -> 385.73184 | K18: =K17/K8 -> 378.95114 | L18: =L17/L8 -> 379.35438 | ... Q18: =Q17/Q8 -> 356.49397
B20: Breakfast Revenues
B22: No of Seats | D22: 100
B24: Hotel Guest Covers | D24: 0.5 | E24: =$D24*E17 -> 5133.6 | F24: =$D24*F17 -> 4876.5554 | G24: =$D24*G17 -> 5199.7493 | H24: =$D24*H17 -> 4419.7608 | I24: =$D24*I17 -> 5652.8978 | J24: =$D24*J17 -> 5785.9776 | K24: =$D24*K17 -> 5873.7426 | L24: =$D24*L17 -> 5879.9929 | ... P24: =$D24*P17 -> 5475.024 | Q24: =SUM(E24:P24) -> 65060.15 | S24: =Q24/$Q$17 -> 0.5
B25: Hotel Guest Cover / Day | E25: =E24/E8 -> 165.6 | F25: =F24/F8 -> 174.16269 | G25: =G24/G8 -> 167.73385 | H25: =H24/H8 -> 147.32536 | I25: =I24/I8 -> 182.35154 | J25: =J24/J8 -> 192.86592 | K25: =K24/K8 -> 189.47557 | L25: =L24/L8 -> 189.67719 | ... Q25: =Q24/Q8 -> 178.24699
B26: Hotel Guest Revenue | D26: 3000 | E26: =$D26*E24 -> 15400800 | F26: =$D26*F24 -> 14629666 | G26: =$D26*G24 -> 15599248 | H26: =$D26*H24 -> 13259283 | I26: =$D26*I24 -> 16958693 | J26: =$D26*J24 -> 17357933 | K26: =$D26*K24 -> 17621228 | L26: =$D26*L24 -> 17639979 | ... P26: =$D26*P24 -> 16425072 | Q26: =SUM(E26:P26) -> 1.9518045e+08
B28: Walk In Covers | D28: 0 | E28: =$D28*$D22*E$8 -> 0 | F28: =$D28*$D22*F$8 -> 0 | G28: =$D28*$D22*G$8 -> 0 | H28: =$D28*$D22*H$8 -> 0 | I28: =$D28*$D22*I$8 -> 0 | J28: =$D28*$D22*J$8 -> 0 | K28: =$D28*$D22*K$8 -> 0 | L28: =$D28*$D22*L$8 -> 0 | ... P28: =$D28*$D22*P$8 -> 0 | Q28: =SUM(E28:P28) -> 0
B29: Walk In Cover / Day | E29: =E28/E8 -> 0 | F29: =F28/F8 -> 0 | G29: =G28/G8 -> 0 | H29: =H28/H8 -> 0 | I29: =I28/I8 -> 0 | J29: =J28/J8 -> 0 | K29: =K28/K8 -> 0 | L29: =L28/L8 -> 0 | ... Q29: =Q28/Q8 -> 0
B30: Walk In Revenues | D30: =D26 -> 3000 | E30: =$D30*E28 -> 0 | F30: =$D30*F28 -> 0 | G30: =$D30*G28 -> 0 | H30: =$D30*H28 -> 0 | I30: =$D30*I28 -> 0 | J30: =$D30*J28 -> 0 | K30: =$D30*K28 -> 0 | L30: =$D30*L28 -> 0 | ... P30: =$D30*P28 -> 0 | Q30: =SUM(E30:P30) -> 0
B32: Total Covers / Month | E32: =E24+E28 -> 5133.6 | F32: =F24+F28 -> 4876.5554 | G32: =G24+G28 -> 5199.7493 | H32: =H24+H28 -> 4419.7608 | I32: =I24+I28 -> 5652.8978 | J32: =J24+J28 -> 5785.9776 | K32: =K24+K28 -> 5873.7426 | L32: =L24+L28 -> 5879.9929 | ... P32: =P24+P28 -> 5475.024 | Q32: =SUM(E32:P32) -> 65060.15
B33: Average Cover / Day | E33: =E32/E8 -> 165.6 | F33: =F32/F8 -> 174.16269 | G33: =G32/G8 -> 167.73385 | H33: =H32/H8 -> 147.32536 | I33: =I32/I8 -> 182.35154 | J33: =J32/J8 -> 192.86592 | K33: =K32/K8 -> 189.47557 | L33: =L32/L8 -> 189.67719 | ... Q33: =Q32/Q8 -> 178.24699
B34: Average Seat Turnover / Day (x) | E34: =E33/$D$22 -> 1.656 | F34: =F33/$D$22 -> 1.7416269 | G34: =G33/$D$22 -> 1.6773385 | H34: =H33/$D$22 -> 1.4732536 | I34: =I33/$D$22 -> 1.8235154 | J34: =J33/$D$22 -> 1.9286592 | K34: =K33/$D$22 -> 1.8947557 | L34: =L33/$D$22 -> 1.8967719 | ... Q34: =Q33/$D$22 -> 1.7824699
B35: Average Check / Cover | E35: =IFERROR(E36/E32,0) -> 3000 | F35: =IFERROR(F36/F32,0) -> 3000 | G35: =IFERROR(G36/G32,0) -> 3000 | H35: =IFERROR(H36/H32,0) -> 3000 | I35: =IFERROR(I36/I32,0) -> 3000 | J35: =IFERROR(J36/J32,0) -> 3000 | K35: =IFERROR(K36/K32,0) -> 3000 | L35: =IFERROR(L36/L32,0) -> 3000 | ... Q35: =IFERROR(Q36/Q32,0) -> 3000
B36: Total Revenues | E36: =E26+E30 -> 15400800 | F36: =F26+F30 -> 14629666 | G36: =G26+G30 -> 15599248 | H36: =H26+H30 -> 13259283 | I36: =I26+I30 -> 16958693 | J36: =J26+J30 -> 17357933 | K36: =K26+K30 -> 17621228 | L36: =L26+L30 -> 17639979 | ... P36: =P26+P30 -> 16425072 | Q36: =SUM(E36:P36) -> 1.9518045e+08
B39: Lunch Revenues
B41: No of Seats | D41: 100
B43: Hotel Guest Covers | D43: 0.05 | E43: =$D43*E17 -> 513.36 | F43: =$D43*F17 -> 487.65554 | G43: =$D43*G17 -> 519.97493 | H43: =$D43*H17 -> 441.97608 | I43: =$D43*I17 -> 565.28978 | J43: =$D43*J17 -> 578.59776 | K43: =$D43*K17 -> 587.37426 | L43: =$D43*L17 -> 587.99929 | ... P43: =$D43*P17 -> 547.5024 | Q43: =SUM(E43:P43) -> 6506.015
B44: Hotel Guest Cover / Day | E44: =E43/E8 -> 16.56 | F44: =F43/F8 -> 17.416269 | G44: =G43/G8 -> 16.773385 | H44: =H43/H8 -> 14.732536 | I44: =I43/I8 -> 18.235154 | J44: =J43/J8 -> 19.286592 | K44: =K43/K8 -> 18.947557 | L44: =L43/L8 -> 18.967719 | ... Q44: =Q43/Q8 -> 17.824699
B45: Hotel Guest Revenue | D45: 3000 | E45: =$D45*E43 -> 1540080 | F45: =$D45*F43 -> 1462966.6 | G45: =$D45*G43 -> 1559924.8 | H45: =$D45*H43 -> 1325928.3 | I45: =$D45*I43 -> 1695869.3 | J45: =$D45*J43 -> 1735793.3 | K45: =$D45*K43 -> 1762122.8 | L45: =$D45*L43 -> 1763997.9 | ... P45: =$D45*P43 -> 1642507.2 | Q45: =SUM(E45:P45) -> 19518045
B47: Walk In Covers | D47: 0.7 | E47: =$D47*$D41*E$8 -> 2170 | F47: =$D47*$D41*F$8 -> 1960 | G47: =$D47*$D41*G$8 -> 2170 | H47: =$D47*$D41*H$8 -> 2100 | I47: =$D47*$D41*I$8 -> 2170 | J47: =$D47*$D41*J$8 -> 2100 | K47: =$D47*$D41*K$8 -> 2170 | L47: =$D47*$D41*L$8 -> 2170 | ... P47: =$D47*$D41*P$8 -> 2170 | Q47: =SUM(E47:P47) -> 25550
B48: Walk In Cover / Day | E48: =E47/E8 -> 70 | F48: =F47/F8 -> 70 | G48: =G47/G8 -> 70 | H48: =H47/H8 -> 70 | I48: =I47/I8 -> 70 | J48: =J47/J8 -> 70 | K48: =K47/K8 -> 70 | L48: =L47/L8 -> 70 | ... Q48: =Q47/Q8 -> 70
B49: Walk In Revenues | D49: =D45 -> 3000 | E49: =$D49*E47 -> 6510000 | F49: =$D49*F47 -> 5880000 | G49: =$D49*G47 -> 6510000 | H49: =$D49*H47 -> 6300000 | I49: =$D49*I47 -> 6510000 | J49: =$D49*J47 -> 6300000 | K49: =$D49*K47 -> 6510000 | L49: =$D49*L47 -> 6510000 | ... P49: =$D49*P47 -> 6510000 | Q49: =SUM(E49:P49) -> 76650000
B51: Total Covers / Month | E51: =E43+E47 -> 2683.36 | F51: =F43+F47 -> 2447.6555 | G51: =G43+G47 -> 2689.9749 | H51: =H43+H47 -> 2541.9761 | I51: =I43+I47 -> 2735.2898 | J51: =J43+J47 -> 2678.5978 | K51: =K43+K47 -> 2757.3743 | L51: =L43+L47 -> 2757.9993 | ... P51: =P43+P47 -> 2717.5024 | Q51: =SUM(E51:P51) -> 32056.015
B52: Average Cover / Day | E52: =E51/E8 -> 86.56 | F52: =F51/F8 -> 87.416269 | G52: =G51/G8 -> 86.773385 | H52: =H51/H8 -> 84.732536 | I52: =I51/I8 -> 88.235154 | J52: =J51/J8 -> 89.286592 | K52: =K51/K8 -> 88.947557 | L52: =L51/L8 -> 88.967719 | ... Q52: =Q51/Q8 -> 87.824699
B53: Average Seat Turnover / Day (x) | E53: =E52/$D$41 -> 0.8656 | F53: =F52/$D$41 -> 0.87416269 | G53: =G52/$D$41 -> 0.86773385 | H53: =H52/$D$41 -> 0.84732536 | I53: =I52/$D$41 -> 0.88235154 | J53: =J52/$D$41 -> 0.89286592 | K53: =K52/$D$41 -> 0.88947557 | L53: =L52/$D$41 -> 0.88967719 | ... Q53: =Q52/$D$41 -> 0.87824699
...

Sheet MOD
A1: ='Room Types'!$A$1 -> Hotel xxxx
A2: Other Revenue
A3: JPY
E6: Month
B7: Year 1 Total | E7: Jan | F7: Feb | G7: Mar | H7: Apr | I7: May | J7: Jun | K7: Jul | L7: Aug | M7: Sep | N7: Oct | O7: Nov | P7: Dec | Q7: Total
B8: No of Days | E8: =Rooms!G7 -> 31 | F8: =Rooms!H7 -> 28 | G8: =Rooms!I7 -> 31 | H8: =Rooms!J7 -> 30 | I8: =Rooms!K7 -> 31 | J8: =Rooms!L7 -> 30 | K8: =Rooms!M7 -> 31 | L8: =Rooms!N7 -> 31 | ... P8: =Rooms!R7 -> 31 | Q8: =SUM(E8:P8) -> 365
B9: Available Room Nights | E9: =Rooms!G9 -> 6417 | F9: =Rooms!H9 -> 5796 | G9: =Rooms!I9 -> 6417 | H9: =Rooms!J9 -> 6210 | I9: =Rooms!K9 -> 6417 | J9: =Rooms!L9 -> 6210 | K9: =Rooms!M9 -> 6417 | L9: =Rooms!N9 -> 6417 | ... P9: =Rooms!R9 -> 6417 | Q9: =SUM(E9:P9) -> 75555
B10: Occupied Room Nights | E10: =Rooms!G10 -> 5133.6 | F10: =Rooms!H10 -> 4876.5554 | G10: =Rooms!I10 -> 5199.7493 | H10: =Rooms!J10 -> 4419.7608 | I10: =Rooms!K10 -> 5652.8978 | J10: =Rooms!L10 -> 5785.9776 | K10: =Rooms!M10 -> 5873.7426 | L10: =Rooms!N10 -> 5879.9929 | ... P10: =Rooms!R10 -> 5475.024 | Q10: =SUM(E10:P10) -> 65060.15
B11: Occupancy | E11: =Rooms!G11 -> 0.8 | F11: =Rooms!H11 -> 0.84136567 | G11: =Rooms!I11 -> 0.81030844 | H11: =Rooms!J11 -> 0.71171672 | I11: =Rooms!K11 -> 0.88092532 | J11: =Rooms!L11 -> 0.93171943 | K11: =Rooms!M11 -> 0.91534091 | L11: =Rooms!N11 -> 0.91631494 | ... Q11: =Rooms!S11 -> 0.86109656
B12: ADR | E12: =Rooms!G12 -> 10000 | F12: =Rooms!H12 -> 10000 | G12: =Rooms!I12 -> 10000 | H12: =Rooms!J12 -> 10000 | I12: =Rooms!K12 -> 10000 | J12: =Rooms!L12 -> 10000 | K12: =Rooms!M12 -> 10000 | L12: =Rooms!N12 -> 10000 | ... Q12: =Rooms!S12 -> 10000
B13: RevPar | E13: =Rooms!G13 -> 8000 | F13: =Rooms!H13 -> 8413.6567 | G13: =Rooms!I13 -> 8103.0844 | H13: =Rooms!J13 -> 7117.1672 | I13: =Rooms!K13 -> 8809.2532 | J13: =Rooms!L13 -> 9317.1943 | K13: =Rooms!M13 -> 9153.4091 | L13: =Rooms!N13 -> 9163.1494 | ... Q13: =Rooms!S13 -> 8610.9656
B14: Total Guest Count | D14: =Q14/Q10 -> 2 | E14: =Rooms!G14 -> 10267.2 | F14: =Rooms!H14 -> 9753.1108 | G14: =Rooms!I14 -> 10399.499 | H14: =Rooms!J14 -> 8839.5217 | I14: =Rooms!K14 -> 11305.796 | J14: =Rooms!L14 -> 11571.955 | K14: =Rooms!M14 -> 11747.485 | L14: =Rooms!N14 -> 11759.986 | ... P14: =Rooms!R14 -> 10950.048 | Q14: =SUM(E14:P14) -> 130120.3
B17: MOD
B19: Revenues
B20: MOD Charge: Yen Per Guest | E20: 50 | F20: 50 | G20: 50 | H20: 50 | I20: 50 | J20: 50 | K20: 50 | L20: 50 | M20: 50 | N20: 50 | O20: 50 | P20: 50 | Q20: 50
B21: No of Guests | E21: =E14 -> 10267.2 | F21: =F14 -> 9753.1108 | G21: =G14 -> 10399.499 | H21: =H14 -> 8839.5217 | I21: =I14 -> 11305.796 | J21: =J14 -> 11571.955 | K21: =K14 -> 11747.485 | L21: =L14 -> 11759.986 | ... P21: =P14 -> 10950.048 | Q21: =SUM(E21:P21) -> 130120.3
B22: MOD Revenue | E22: =E20*E21 -> 513360 | F22: =F20*F21 -> 487655.54 | G22: =G20*G21 -> 519974.93 | H22: =H20*H21 -> 441976.08 | I22: =I20*I21 -> 565289.78 | J22: =J20*J21 -> 578597.76 | K22: =K20*K21 -> 587374.26 | L22: =L20*L21 -> 587999.29 | ... P22: =P20*P21 -> 547502.4 | Q22: =SUM(E22:P22) -> 6506015
B24: COGS% | E24: 0.5
B25: COGS | E25: =$E$24*E22 -> 256680 | F25: =$E$24*F22 -> 243827.77 | G25: =$E$24*G22 -> 259987.46 | H25: =$E$24*H22 -> 220988.04 | I25: =$E$24*I22 -> 282644.89 | J25: =$E$24*J22 -> 289298.88 | K25: =$E$24*K22 -> 293687.13 | L25: =$E$24*L22 -> 293999.65 | ... P25: =$E$24*P22 -> 273751.2 | Q25: =SUM(E25:P25) -> 3253007.5
B28: Tenant Income
B30: Tenant 1
C31: sqm | D31: Tsubo
B32: Area | C32: =D32*3.30578 -> 0 | D32: 0
B33: Rent / Tsubo / Mo | D33: 0 | E33: =$D$32*$D$33 -> 0 | F33: =$D$32*$D$33 -> 0 | G33: =$D$32*$D$33 -> 0 | H33: =$D$32*$D$33 -> 0 | I33: =$D$32*$D$33 -> 0 | J33: =$D$32*$D$33 -> 0 | K33: =$D$32*$D$33 -> 0 | L33: =$D$32*$D$33 -> 0 | ... P33: =$D$32*$D$33 -> 0 | Q33: =SUM(E33:P33) -> 0
B34: Occupancy | D34: 0 | E34: =$D$34*E33 -> 0 | F34: =$D$34*F33 -> 0 | G34: =$D$34*G33 -> 0 | H34: =$D$34*H33 -> 0 | I34: =$D$34*I33 -> 0 | J34: =$D$34*J33 -> 0 | K34: =$D$34*K33 -> 0 | L34: =$D$34*L33 -> 0 | ... P34: =$D$34*P33 -> 0 | Q34: =SUM(E34:P34) -> 0
B37: Tenant 2
C38: sqm | D38: Tsubo
B39: Area | C39: =D39*3.30578 -> 0 | D39: 0
B40: Rent / Tsubo / Mo | D40: 0 | E40: =$D$39*$D$40 -> 0 | F40: =$D$39*$D$40 -> 0 | G40: =$D$39*$D$40 -> 0 | H40: =$D$39*$D$40 -> 0 | I40: =$D$39*$D$40 -> 0 | J40: =$D$39*$D$40 -> 0 | K40: =$D$39*$D$40 -> 0 | L40: =$D$39*$D$40 -> 0 | ... P40: =$D$39*$D$40 -> 0 | Q40: =SUM(E40:P40) -> 0
B41: Occupancy | D41: 0 | E41: =$D$41*E40 -> 0 | F41: =$D$41*F40 -> 0 | G41: =$D$41*G40 -> 0 | H41: =$D$41*H40 -> 0 | I41: =$D$41*I40 -> 0 | J41: =$D$41*J40 -> 0 | K41: =$D$41*K40 -> 0 | L41: =$D$41*L40 -> 0 | ... P41: =$D$41*P40 -> 0 | Q41: =SUM(E41:P41) -> 0
B44: Tenant 3
C45: sqm | D45: Tsubo
B46: Area | C46: =D46*3.30578 -> 0 | D46: 0
B47: Rent / Tsubo / Mo | D47: 0 | E47: =$D$46*$D$47 -> 0 | F47: =$D$46*$D$47 -> 0 | G47: =$D$46*$D$47 -> 0 | H47: =$D$46*$D$47 -> 0 | I47: =$D$46*$D$47 -> 0 | J47: =$D$46*$D$47 -> 0 | K47: =$D$46*$D$47 -> 0 | L47: =$D$46*$D$47 -> 0 | ... P47: =$D$46*$D$47 -> 0 | Q47: =SUM(E47:P47) -> 0
B48: Occupancy | D48: 0 | E48: =$D$48*E47 -> 0 | F48: =$D$48*F47 -> 0 | G48: =$D$48*G47 -> 0 | H48: =$D$48*H47 -> 0 | I48: =$D$48*I47 -> 0 | J48: =$D$48*J47 -> 0 | K48: =$D$48*K47 -> 0 | L48: =$D$48*L47 -> 0 | ... P48: =$D$48*P47 -> 0 | Q48: =SUM(E48:P48) -> 0
B52: Parking Income
B54: Parking
D55: Tsubo
B56: No of Spaces | D56: 48
B57: Parking Fee / Day | D57: 1500 | E57: =$D$56*$D$57*E8 -> 2232000 | F57: =$D$56*$D$57*F8 -> 2016000 | G57: =$D$56*$D$57*G8 -> 2232000 | H57: =$D$56*$D$57*H8 -> 2160000 | I57: =$D$56*$D$57*I8 -> 2232000 | J57: =$D$56*$D$57*J8 -> 2160000 | K57: =$D$56*$D$57*K8 -> 2232000 | L57: =$D$56*$D$57*L8 -> 2232000 | ... P57: =$D$56*$D$57*P8 -> 2232000 | Q57: =SUM(E57:P57) -> 26280000
...

Sheet Undist Expense
A1: ='Room Types'!$A$1 -> Hotel xxxx
A2: Undistributable Expenses
A3: JPY
E6: Month
B7: Year 1 Total | E7: Jan | F7: Feb | G7: Mar | H7: Apr | I7: May | J7: Jun | K7: Jul | L7: Aug | M7: Sep | N7: Oct | O7: Nov | P7: Dec | Q7: Total
B8: No of Days | C8: =Rooms!S7 -> 365 | E8: =Rooms!G7 -> 31 | F8: =Rooms!H7 -> 28 | G8: =Rooms!I7 -> 31 | H8: =Rooms!J7 -> 30 | I8: =Rooms!K7 -> 31 | J8: =Rooms!L7 -> 30 | K8: =Rooms!M7 -> 31 | L8: =Rooms!N7 -> 31 | ... P8: =Rooms!R7 -> 31 | Q8: =SUM(E8:P8) -> 365
B9: Available Room Nights | C9: =Rooms!S9 -> 75555 | E9: =Rooms!G9 -> 6417 | F9: =Rooms!H9 -> 5796 | G9: =Rooms!I9 -> 6417 | H9: =Rooms!J9 -> 6210 | I9: =Rooms!K9 -> 6417 | J9: =Rooms!L9 -> 6210 | K9: =Rooms!M9 -> 6417 | L9: =Rooms!N9 -> 6417 | ... P9: =Rooms!R9 -> 6417 | Q9: =SUM(E9:P9) -> 75555
B10: Occupied Room Nights | C10: =Rooms!S10 -> 65060.15 | E10: =Rooms!G10 -> 5133.6 | F10: =Rooms!H10 -> 4876.5554 | G10: =Rooms!I10 -> 5199.7493 | H10: =Rooms!J10 -> 4419.7608 | I10: =Rooms!K10 -> 5652.8978 | J10: =Rooms!L10 -> 5785.9776 | K10: =Rooms!M10 -> 5873.7426 | L10: =Rooms!N10 -> 5879.9929 | ... P10: =Rooms!R10 -> 5475.024 | Q10: =SUM(E10:P10) -> 65060.15
B11: Occupancy | C11: =C10/C9 -> 0.86109656 | E11: =E10/E9 -> 0.8 | F11: =F10/F9 -> 0.84136567 | G11: =G10/G9 -> 0.81030844 | H11: =H10/H9 -> 0.71171672 | I11: =I10/I9 -> 0.88092532 | J11: =J10/J9 -> 0.93171943 | K11: =K10/K9 -> 0.91534091 | L11: =L10/L9 -> 0.91631494 | ... Q11: =Q10/Q9 -> 0.86109656
B12: ADR | C12: =Rooms!S12 -> 10000 | E12: =Rooms!G12 -> 10000 | F12: =Rooms!H12 -> 10000 | G12: =Rooms!I12 -> 10000 | H12: =Rooms!J12 -> 10000 | I12: =Rooms!K12 -> 10000 | J12: =Rooms!L12 -> 10000 | K12: =Rooms!M12 -> 10000 | L12: =Rooms!N12 -> 10000 | ... Q12: =Rooms!S12 -> 10000
B13: RevPar | C13: =Rooms!S13 -> 8610.9656 | E13: =E12*E11 -> 8000 | F13: =F12*F11 -> 8413.6567 | G13: =G12*G11 -> 8103.0844 | H13: =H12*H11 -> 7117.1672 | I13: =I12*I11 -> 8809.2532 | J13: =J12*J11 -> 9317.1943 | K13: =K12*K11 -> 9153.4091 | L13: =L12*L11 -> 9163.1494 | ... Q13: =Q12*Q11 -> 8610.9656
B14: Total Guest Count | C14: =Rooms!S14 -> 130120.3 | D14: =C14/C10 -> 2 | E14: =Rooms!G14 -> 10267.2 | F14: =Rooms!H14 -> 9753.1108 | G14: =Rooms!I14 -> 10399.499 | H14: =Rooms!J14 -> 8839.5217 | I14: =Rooms!K14 -> 11305.796 | J14: =Rooms!L14 -> 11571.955 | K14: =Rooms!M14 -> 11747.485 | L14: =Rooms!N14 -> 11759.986 | ... P14: =Rooms!R14 -> 10950.048 | Q14: =SUM(E14:P14) -> 130120.3 | R14: =Q14/Q10 -> 2
B17: Revenues | C17: Year 1 Total
B18: Rooms | C18: =Proforma!D27 -> 6.506015e+08
B19: Restaurant | C19: =Proforma!D28 -> 5.6936504e+08
B20: MOD | C20: =Proforma!D29 -> 19646015
B21: Total | C21: =SUM(C18:C20) -> 1.2396126e+09
B22: Check | C22: =Proforma!D30 -> 1.2396126e+09
B24: Proforma KPIs | E24: Year 1 | F24: Year 2 | G24: Year 3 | H24: Year 4 | I24: Year 5
B25: No of Rooms | E25: =Rooms!G104 -> 207 | F25: =Rooms!H104 -> 207 | G25: =Rooms!I104 -> 207 | H25: =Rooms!J104 -> 207 | I25: =Rooms!K104 -> 207
B26: Occupancy | E26: =Rooms!G105 -> 0.86109656 | F26: =Rooms!H105 -> 0.89109656 | G26: =Rooms!I105 -> 0.92109656 | H26: =Rooms!J105 -> 0.94109656 | I26: =Rooms!K105 -> 0.95609656
F28: y | G28: y | H28: y | K28: y
E29: x | I29: x | K29: x | L29: x
B30: Staffing Salary | E30: Base Mo Salary | F30: Welfare Salary | G30: Transportation | H30: Housing | I30: Bonus | J30: Welfare Bonus | K30: Welfare Total | L30: Total Mo | M30: Total Yr | O30: Year 1 Month
B31: A&G
B32: Project Leader | C32: Project Leader | D32: DH | E32: 0 | F32: =+E32*0.16 -> 0 | G32: 0 | H32: 0 | I32: =+(E32*2)/12 -> 0 | J32: =+I32*0.16 -> 0 | K32: =F32+G32+H32+J32 -> 0 | L32: =K32+E32+I32 -> 0 | M32: =L32*12 -> 0 | O32: =L32*E65 -> 0
B33: Administration | C33: Hotel Manager | D33: Manager | E33: 600000 | F33: =+E33*0.16 -> 96000 | G33: 10000 | H33: 0 | I33: =+(E33*2)/12 -> 100000 | J33: =+I33*0.16 -> 16000 | K33: =F33+G33+H33+J33 -> 122000 | L33: =K33+E33+I33 -> 822000 | M33: =L33*12 -> 9864000 | O33: =L33*E66 -> 822000
B34: Executive Office | C34: Assistant to GM | D34: R&F | E34: 0 | F34: =+E34*0.16 -> 0 | G34: 0 | H34: 0 | I34: =+(E34*2)/12 -> 0 | J34: =+I34*0.16 -> 0 | K34: =F34+G34+H34+J34 -> 0 | L34: =K34+E34+I34 -> 0 | M34: =L34*12 -> 0 | O34: =L34*E67 -> 0
B35: Admin & Finance | C35: Dir of Admin & Finance | D35: DH | E35: 0 | F35: =+E35*0.16 -> 0 | G35: 0 | H35: 0 | I35: =+(E35*2)/12 -> 0 | J35: =+I35*0.16 -> 0 | K35: =F35+G35+H35+J35 -> 0 | L35: =K35+E35+I35 -> 0 | M35: =L35*12 -> 0 | O35: =L35*E68 -> 0
B36: Finance | C36: Manager | D36: MGR | E36: 0 | F36: =+E36*0.16 -> 0 | G36: 0 | H36: 0 | I36: =+(E36*2)/12 -> 0 | J36: =+I36*0.16 -> 0 | K36: =F36+G36+H36+J36 -> 0 | L36: =K36+E36+I36 -> 0 | M36: =L36*12 -> 0 | O36: =L36*E69 -> 0
B37: Finance | C37: Assistant Manager | D37: AM | E37: 0 | F37: =+E37*0.16 -> 0 | G37: 0 | H37: 0 | I37: =+(E37*2)/12 -> 0 | J37: =+I37*0.16 -> 0 | K37: =F37+G37+H37+J37 -> 0 | L37: =K37+E37+I37 -> 0 | M37: =L37*12 -> 0 | O37: =L37*E70 -> 0
B38: Finance | C38: Team Leader | D38: TL | E38: 0 | F38: =+E38*0.16 -> 0 | G38: 0 | H38: 0 | I38: =+(E38*2)/12 -> 0 | J38: =+I38*0.16 -> 0 | K38: =F38+G38+H38+J38 -> 0 | L38: =K38+E38+I38 -> 0 | M38: =L38*12 -> 0 | O38: =L38*E71 -> 0
B39: Finance | C39: Finance Officer | D39: R&F | E39: 0 | F39: =+E39*0.16 -> 0 | G39: 0 | H39: 0 | I39: =+(E39*2)/12 -> 0 | J39: =+I39*0.16 -> 0 | K39: =F39+G39+H39+J39 -> 0 | L39: =K39+E39+I39 -> 0 | M39: =L39*12 -> 0 | O39: =L39*E72 -> 0
B40: Information System | C40: Manager | D40: MGR | E40: 0 | F40: =+E40*0.16 -> 0 | G40: 0 | H40: 0 | I40: =+(E40*2)/12 -> 0 | J40: =+I40*0.16 -> 0 | K40: =F40+G40+H40+J40 -> 0 | L40: =K40+E40+I40 -> 0 | M40: =L40*12 -> 0 | O40: =L40*E73 -> 0
B41: Information System | C41: Assistant Manager | D41: AM | E41: 0 | F41: =+E41*0.16 -> 0 | G41: 0 | H41: 0 | I41: =+(E41*2)/12 -> 0 | J41: =+I41*0.16 -> 0 | K41: =F41+G41+H41+J41 -> 0 | L41: =K41+E41+I41 -> 0 | M41: =L41*12 -> 0 | O41: =L41*E74 -> 0
B42: Material | C42: Manager | D42: MGR | E42: 0 | F42: =+E42*0.16 -> 0 | G42: 0 | H42: 0 | I42: =+(E42*2)/12 -> 0 | J42: =+I42*0.16 -> 0 | K42: =F42+G42+H42+J42 -> 0 | L42: =K42+E42+I42 -> 0 | M42: =L42*12 -> 0 | O42: =L42*E75 -> 0
B43: Material | C43: Assistant Manager | D43: AM | E43: 0 | F43: =+E43*0.16 -> 0 | G43: 0 | H43: 0 | I43: =+(E43*2)/12 -> 0 | J43: =+I43*0.16 -> 0 | K43: =F43+G43+H43+J43 -> 0 | L43: =K43+E43+I43 -> 0 | M43: =L43*12 -> 0 | O43: =L43*E76 -> 0
... B49: Learning/Training | C49: Assistant Manager | D49: AM | E49: 0 | F49: =+E49*0.16 -> 0 | G49: 0 | H49: 0 | I49: =+(E49*2)/12 -> 0 | J49: =+I49*0.16 -> 0 | K49: =F49+G49+H49+J49 -> 0 | L49: =K49+E49+I49 -> 0 | M49: =L49*12 -> 0 | O49: =L49*E82 -> 0
F50: =+E50*0.16 -> 0 | I50: =+(E50*2)/12 -> 0 | J50: =+I50*0.16 -> 0
B51: Sales & Marketing
...

Sheet Staffing
A1: ='Undist Expense'!A1 -> Hotel xxxx
A2: Staffing
A3: JPY
B6: Head Count / Salary | C6: Year 1 | E6: Year 2 | G6: Year 3 | I6: Year 4 | K6: Year 5 | N6: Year 1 Month
C7: No of Staff | D7: Full Salary | E7: No of Staff | F7: Full Salary | G7: No of Staff | H7: Full Salary | I7: No of Staff | J7: Full Salary | K7: No of Staff | L7: Full Salary
B9: Rooms | C9: =Rooms!G205 -> 14 | D9: =Rooms!H205 -> 55306560 | E9: =Rooms!I205 -> 14 | F9: =Rooms!J205 -> 55306560 | G9: =Rooms!K205 -> 14 | H9: =Rooms!L205 -> 55306560 | I9: =Rooms!M205 -> 14 | J9: =Rooms!N205 -> 55306560 | ... L9: =Rooms!P205 -> 55306560 | N9: =D9/12 -> 4608880
B11: Restaurant | C11: =Restaurant!E189 -> 33 | D11: =Restaurant!F189 -> 124460800 | E11: =Restaurant!G189 -> 33 | F11: =Restaurant!H189 -> 124460800 | G11: =Restaurant!I189 -> 33 | H11: =Restaurant!J189 -> 124460800 | I11: =Restaurant!K189 -> 33 | J11: =Restaurant!L189 -> 124460800 | ... L11: =Restaurant!N189 -> 124460800 | N11: =D11/12 -> 10371733
B13: Other | C13: =MOD!E81 -> 0 | D13: =MOD!E91 -> 0 | E13: =MOD!F81 -> 0 | F13: =MOD!F91 -> 0 | G13: =MOD!G81 -> 0 | H13: =MOD!G91 -> 0 | I13: =MOD!H81 -> 0 | J13: =MOD!H91 -> 0 | K13: =MOD!I81 -> 0 | L13: =MOD!I91 -> 0 | N13: =D13/12 -> 0
B15: A&G | C15: ='Undist Expense'!E182 -> 1 | D15: ='Undist Expense'!F182 -> 9864000 | E15: ='Undist Expense'!G182 -> 1 | F15: ='Undist Expense'!H182 -> 9864000 | G15: ='Undist Expense'!I182 -> 1 | H15: ='Undist Expense'!J182 -> 9864000 | I15: ='Undist Expense'!K182 -> 1 | J15: ='Undist Expense'!L182 -> 9864000 | ... L15: ='Undist Expense'!N182 -> 9864000 | N15: =D15/12 -> 822000
B17: Sales & Marketing | C17: ='Undist Expense'!E183 -> 0 | D17: ='Undist Expense'!F183 -> 0 | E17: ='Undist Expense'!G183 -> 0 | F17: ='Undist Expense'!H183 -> 0 | G17: ='Undist Expense'!I183 -> 0 | H17: ='Undist Expense'!J183 -> 0 | I17: ='Undist Expense'!K183 -> 0 | J17: ='Undist Expense'!L183 -> 0 | ... L17: ='Undist Expense'!N183 -> 0 | N17: =D17/12 -> 0
B19: Enginnering | C19: ='Undist Expense'!E184 -> 0 | D19: ='Undist Expense'!F184 -> 0 | E19: ='Undist Expense'!G184 -> 0 | F19: ='Undist Expense'!H184 -> 0 | G19: ='Undist Expense'!I184 -> 0 | H19: ='Undist Expense'!J184 -> 0 | I19: ='Undist Expense'!K184 -> 0 | J19: ='Undist Expense'!L184 -> 0 | ... L19: ='Undist Expense'!N184 -> 0 | N19: =D19/12 -> 0
B21: Total | C21: =SUM(C9:C19) -> 48 | D21: =SUM(D9:D19) -> 189631360 | E21: =SUM(E9:E19) -> 48 | F21: =SUM(F9:F19) -> 189631360 | G21: =SUM(G9:G19) -> 48 | H21: =SUM(H9:H19) -> 189631360 | I21: =SUM(I9:I19) -> 48 | J21: =SUM(J9:J19) -> 189631360 | ... L21: =SUM(L9:L19) -> 189631360 | N21: =SUM(N9:N19) -> 15802613
B22: Check | D22: =Proforma!D24 -> 189631360 | F22: =Proforma!G24 -> 189631360 | H22: =Proforma!J24 -> 189631360 | J22: =Proforma!M24 -> 189631360 | L22: =Proforma!P24 -> 189631360 | N22: =D22/12 -> 15802613
B25: Head Count / Salary | C25: Year 1 | E25: Year 2 | G25: Year 3 | I25: Year 4 | K25: Year 5
C26: No of Staff | D26: Full Salary | E26: No of Staff | F26: Full Salary | G26: No of Staff | H26: Full Salary | I26: No of Staff | J26: Full Salary | K26: No of Staff | L26: Full Salary
B28: Rooms | C28: =C9 -> 14 | D28: =D9 -> 55306560 | E28: =E9 -> 14 | F28: =F9 -> 55306560 | G28: =G9 -> 14 | H28: =H9 -> 55306560 | I28: =I9 -> 14 | J28: =J9 -> 55306560 | ... L28: =L9 -> 55306560
B29: Restaurant | C29: =C11 -> 33 | D29: =D11 -> 124460800 | E29: =E11 -> 33 | F29: =F11 -> 124460800 | G29: =G11 -> 33 | H29: =H11 -> 124460800 | I29: =I11 -> 33 | J29: =J11 -> 124460800 | ... L29: =L11 -> 124460800
B30: Other | C30: =C13 -> 0 | D30: =D13 -> 0 | E30: =E13 -> 0 | F30: =F13 -> 0 | G30: =G13 -> 0 | H30: =H13 -> 0 | I30: =I13 -> 0 | J30: =J13 -> 0 | ... L30: =L13 -> 0
B31: Undistributable | C31: =C15+C17+C19 -> 1 | D31: =D15+D17+D19 -> 9864000 | E31: =E15+E17+E19 -> 1 | F31: =F15+F17+F19 -> 9864000 | G31: =G15+G17+G19 -> 1 | H31: =H15+H17+H19 -> 9864000 | I31: =I15+I17+I19 -> 1 | J31: =J15+J17+J19 -> 9864000 | ... L31: =L15+L17+L19 -> 9864000
B32: Total | C32: =SUM(C28:C31) -> 48 | D32: =SUM(D28:D31) -> 189631360 | E32: =SUM(E28:E31) -> 48 | F32: =SUM(F28:F31) -> 189631360 | G32: =SUM(G28:G31) -> 48 | H32: =SUM(H28:H31) -> 189631360 | I32: =SUM(I28:I31) -> 48 | J32: =SUM(J28:J31) -> 189631360 | ... L32: =SUM(L28:L31) -> 189631360
B35: Head Count; FT / PT | C35: Year 1 | E35: Year 2 | G35: Year 3 | I35: Year 4 | K35: Year 5
C36: No of Staff | E36: No of Staff | G36: No of Staff | I36: No of Staff | K36: No of Staff
B38: Rooms | C38: =C39+C40 -> 14 | E38: =E39+E40 -> 14 | G38: =G39+G40 -> 14 | I38: =I39+I40 -> 14 | K38: =K39+K40 -> 14
B39: FT | C39: =Rooms!G207 -> 6 | E39: =Rooms!I207 -> 6 | G39: =Rooms!K207 -> 6 | I39: =Rooms!M207 -> 6 | K39: =Rooms!O207 -> 6
B40: PT | C40: =Rooms!G208 -> 8 | E40: =Rooms!I208 -> 8 | G40: =Rooms!K208 -> 8 | I40: =Rooms!M208 -> 8 | K40: =Rooms!O208 -> 8
B41: Restaurant | C41: =C42+C43 -> 33 | E41: =E42+E43 -> 33 | G41: =G42+G43 -> 33 | I41: =I42+I43 -> 33 | K41: =K42+K43 -> 33
B42: FT | C42: =Restaurant!E191 -> 13 | E42: =Restaurant!G191 -> 13 | G42: =Restaurant!I191 -> 13 | I42: =Restaurant!K191 -> 13 | K42: =Restaurant!M191 -> 13
B43: PT | C43: =Restaurant!E192 -> 20 | E43: =Restaurant!G192 -> 20 | G43: =Restaurant!I192 -> 20 | I43: =Restaurant!K192 -> 20 | K43: =Restaurant!M192 -> 20
B44: Other | C44: =C45+C46 -> 0 | E44: =E45+E46 -> 0 | G44: =G45+G46 -> 0 | I44: =I45+I46 -> 0 | K44: =K45+K46 -> 0
B45: FT | C45: =MOD!E122 -> 0 | E45: =MOD!G122 -> 0 | G45: =MOD!I122 -> 0 | I45: =MOD!K122 -> 0 | K45: =MOD!M122 -> 0
B46: PT | C46: =MOD!E123 -> 0 | E46: =MOD!G123 -> 0 | G46: =MOD!I123 -> 0 | I46: =MOD!K123 -> 0 | K46: =MOD!M123 -> 0
B47: Undistributable | C47: =C48+C49 -> 1 | E47: =E48+E49 -> 1 | G47: =G48+G49 -> 1 | I47: =I48+I49 -> 1 | K47: =K48+K49 -> 1
B48: FT | C48: ='Undist Expense'!E187 -> 1 | E48: ='Undist Expense'!G187 -> 1 | G48: ='Undist Expense'!I187 -> 1 | I48: ='Undist Expense'!K187 -> 1 | K48: ='Undist Expense'!M187 -> 1
B49: PT | C49: ='Undist Expense'!E188 -> 0 | E49: ='Undist Expense'!G188 -> 0 | G49: ='Undist Expense'!I188 -> 0 | I49: ='Undist Expense'!K188 -> 0 | K49: ='Undist Expense'!M188 -> 0
B50: Total | C50: =C51+C52 -> 48 | D50: =C38+C41+C44+C47 -> 48 | E50: =E51+E52 -> 48 | F50: =E38+E41+E44+E47 -> 48 | G50: =G51+G52 -> 48 | H50: =G38+G41+G44+G47 -> 48 | I50: =I51+I52 -> 48 | J50: =I38+I41+I44+I47 -> 48 | K50: =K51+K52 -> 48 | L50: =K38+K41+K44+K47 -> 48
B51: FT | C51: =C39+C42+C48+C45 -> 20 | E51: =E39+E42+E48+E45 -> 20 | G51: =G39+G42+G48+G45 -> 20 | I51: =I39+I42+I48+I45 -> 20 | K51: =K39+K42+K48+K45 -> 20
B52: PT | C52: =C40+C43+C49+C46 -> 28 | E52: =E40+E43+E49+E46 -> 28 | G52: =G40+G43+G49+G46 -> 28 | I52: =I40+I43+I49+I46 -> 28 | K52: =K40+K43+K49+K46 -> 28
